Workbook

Sheet Incidents
A1: ID | B1: Year | C1: Date / Period | D1: Organisation(s) Affected | E1: Sector (Primary) | F1: Sub-sector | G1: Other Sectors Affected | H1: Incident Type | I1: Method / Attack Vector | J1: Threat Actor (as reported) | K1: Reported Loss (UGX bn) | L1: Reported Loss (USD m) | M1: Data / Systems Affected | N1: Outcome / Response | O1: Confidence | P1: Primary Source(s) | Q1: Source URL | R1: Notes
A2: UG-001 | B2: 2011 | C2: May–Dec 2011 (exposed Mar 2012) | D2: MTN Uganda – Mobile Money | E2: Financial Services | F2: Mobile money (telco-operated) | G2: Telecommunications | H2: Insider fraud | I2: Staff abused privileged access and an unreconciled suspense account while the mobile money platform had capacity problems; fictitious subscriber accounts used | J2: Insiders (MTN employees) | K2: 10 | L2: 3.4 | M2: Mobile money suspense account / e-float | N2: Ex-employees charged in Anti-Corruption Court (embezzlement, electronic fraud); MTN tightened controls | O2: Confirmed | P2: CGAP; Daily Monitor | Q2: https://www.cgap.org/blog/fraud-in-uganda-how-millions-were-lost-to-internal-collusion | R2: Figures in court coverage range UGX 5–10bn; CGAP cites UGX 10bn (USD 3.4m).
A3: UG-002 | B3: 2012 | C3: Reported Jun 2012 (ran ~1 year) | D3: Uganda Revenue Authority (URA) – customs systems | E3: Government & Public Sector | F3: Tax / revenue administration | H3: Unauthorised access / system fraud | I3: Illegal access to customs system to push fraudulent transactions; URA did not rule out insider help | J3: 4 suspects incl. an ICT specialist and clearing agents | K3: 2 | M3: Customs clearance system | N3: 4 arrested by URA enforcement and police | O3: Confirmed | P3: The Independent; PC Tech Magazine | Q3: https://www.independent.co.ug/ugly-face-hacking/ | R3: Losses of about UGX 2bn over roughly a year.
A4: UG-003 | B4: 2012 | C4: Aug 2012 | D4: Office of the Prime Minister, Parliament, Uganda Securities Exchange, Uganda Law Society websites; JLOS database | E4: Government & Public Sector | F4: Central government websites | G4: Financial Services; Legal | H4: Website defacement / hacktivism | I4: Websites defaced with spoof statements; JLOS admin passwords exposed | J4: Anonymous / #TheEliteSociety; @PinkNinj4 | M4: Public websites; admin credentials | N4: Sites restored | O4: Reported | P4: Global Voices; NBC News (Reuters); PinkNews | Q4: https://www.nbcnews.com/news/world/activists-hack-uganda-government-website-over-gay-rights-flna946822 | R4: Protest against anti-homosexuality bill. By Dec 2012 Anonymous claimed ~9 .go.ug and ~6 commercial sites compromised (PRI).
A5: UG-004 | B5: 2013 | C5: May 2013 | D5: 40+ websites: ministries (Finance, ICT, Agriculture, Public Service), KCCA, NITA-U, PPDA, Uganda Police, NARO, district local governments; plus private sites | E5: Government & Public Sector | F5: Central & local government websites | G5: Financial Services; Media; Hospitality | H5: Website defacement / hacktivism | I5: Mass defacement – pages replaced with group message | J5: Islamic Ghosts Team | M5: Public websites | N5: Sites taken offline for restoration | O5: Reported | P5: PC Tech Magazine | Q5: https://pctechmag.com/2013/05/over-40-uganda-government-websites-hacked-by-islamic-ghosts-team/ | R5: Private victims included Opportunity Bank, Pride Microfinance, WBS TV and hotels.
A6: UG-005 | B6: 2014 | C6: Reported Jun 2014 | D6: Makerere University – student results | E6: Education | F6: Higher education | H6: Unauthorised access / records manipulation | I6: Alleged alteration of student grades in exchange for payment | J6: IT PhD student | M6: Academic results records | N6: Suspect arrested | O6: Reported | P6: PC Tech Magazine (NTV) | Q6: https://pctechmag.com/2014/06/makerere-university-hacker-who-was-altering-student-results-arrested-video/
A7: UG-006 | B7: 2014 | C7: Reported Jul 2014 (convicted Apr 2015) | D7: MTN Uganda – Mobile Money | E7: Financial Services | F7: Mobile money (telco-operated) | G7: Telecommunications | H7: Insider fraud | I7: Illegal access to mobile money system; funds wired to 7 registered agent lines | J7: Insiders (staff, agents, contractors) | K7: 3.15 | M7: Mobile money information system | N7: 6 convicted by Anti-Corruption Court (Apr 2015); 3 acquitted | O7: Confirmed | P7: NextBillion (citing PC Tech Magazine / TechMoran) | Q7: https://nextbillion.net/news/former-mtn-uganda-staff-get-9-years-jail-for-mobile-money-fraud
A8: UG-007 | B8: 2016 | C8: c. 2015–16 (exact date unverified) | D8: Ministry of Foreign Affairs website + 20 Uganda High Commission websites | E8: Government & Public Sector | F8: Central government websites | H8: Website defacement / hacktivism | I8: Mass defacement, likely via shared server | J8: GeNiuS-JorDan | M8: Public websites | N8: Sites restored | O8: Reported | P8: HackRead | Q8: https://hackread.com/uganda-high-commission-website-hacked/ | R8: Anti-war message; date approximate – verify before citing.
A9: UG-008 | B9: 2017 | C9: Feb–Sep 2017 | D9: Makerere University – academic records system | E9: Education | F9: Higher education | H9: Unauthorised access / records manipulation | I9: Results system infiltrated to falsify marks and add ineligible graduands | J9: Insiders (staff, alumni, students – 88 implicated) | M9: 14,895 transcripts withheld; 58 names withdrawn from graduation list | N9: Transcript system shut down; staff dismissed; police referral | O9: Confirmed | P9: Daily Monitor; University World News | Q9: https://www.monitor.co.ug/uganda/news/education/makerere-withholds-14-000-transcripts-over-fake-marks-1693578
A10: UG-009 | B10: 2019 | C10: Jan 2019 | D10: Ministry of Gender, Labour & Social Development – External Labour Information Management System | E10: Government & Public Sector | F10: Central government systems | H10: Data breach / exposure | I10: Intrusion to steal labour-export recruitment data; system crashed | J10: Suspected insider | M10: Labour export company vetting records & documents | N10: Under investigation | O10: Reported | P10: Daily Monitor (via InfoSec News) | Q10: https://seclists.org/isn/2019/Jan/64
A11: UG-010 | B11: 2019 | C11: 2019 (year-long) | D11: Multiple banks & mobile money providers | E11: Financial Services | F11: Banking & mobile money | G11: Telecommunications | H11: SIM-swap fraud | I11: 519 fraudulently swapped pre-registered SIM cards used to transfer money; duplicate national IDs used for SIM registration | J11: Organised fraud rings | M11: Customer bank & mobile money accounts | N11: Police investigations | O11: Reported | P11: Serianu – Africa Cybersecurity Report: Uganda 2019/2020 | Q11: https://www.serianu.com/downloads/UgandaCyberSecurityReport2020.pdf | R11: Campaign-level entry, not a single incident.
A12: UG-011 | B12: 2020 | C12: 1–3 Oct 2020 | D12: Pegasus Technologies (payments aggregator) – affecting MTN MoMo, Airtel Money, Stanbic Bank, Bank of Africa | E12: Financial Services | F12: Payments aggregator / bank-to-wallet | G12: Telecommunications | H12: Unauthorised access / system fraud | I12: System manipulation of bank-to-wallet transfers; ~1,630 fraudulently registered SIM cards used to cash out at agents | J12: Insider-enabled (Stanbic employee who was also Pegasus external sysadmin) + cash-out network | K12: 10.441 | M12: Bank-to-mobile-money integration platform | N12: Bank-to-wallet services suspended; suspects arrested and charged (Dec 2020) | O12: Confirmed | P12: Eagle Online (citing CID); CEO East Africa; PML Daily | Q12: https://eagle.co.ug/2020/12/11/stanbic-bank-employee-arrested-over-recent-shs10-billion-electronic-scam | R12: Early estimates were ~USD 3.2m; police later put loss at UGX 10.44bn.
A13: UG-012 | B13: 2021 | C13: 16 Jan 2021 | D13: Parliament of Uganda and other government & media websites | E13: Government & Public Sector | F13: Central government websites | G13: Media | H13: Website defacement / hacktivism | I13: Website attacks and information leaks | J13: Anonymousx64 | M13: Public websites | O13: Reported | P13: TechRafiki | Q13: https://techrafiki.com/uganda-government-websites-hacked-by-anonymous/ | R13: Protest over election-period internet shutdown.
A14: UG-013 | B14: 2021 | C14: Feb–Mar 2021 | D14: Civil Service College Uganda website; MPs' personal data | E14: Government & Public Sector | F14: Central government websites / data | H14: Website defacement / hacktivism | I14: Website defaced twice; MPs' personal & next-of-kin data leaked | J14: YourAnonWolf (Anonymous-affiliated) | M14: Website; MPs' personal data | O14: Reported | P14: The Observer | Q14: https://observer.ug/news/hackers-plan-attacks-on-government-websites/ | R14: Includes a data leak component.
A15: UG-014 | B15: 2022 | C15: 2022 (reported Nov 2022) | D15: UGAFODE Microfinance Ltd | E15: Financial Services | F15: Microfinance (MDI) | H15: Unauthorised access / system fraud | I15: Unauthorised electronic theft (method not disclosed) | J15: Unknown | K15: 0.4 | M15: Institution funds | O15: Reported | P15: The Citizen / The EastAfrican | Q15: https://www.thecitizen.co.tz/tanzania/business/how-hackers-stole-billions-from-airtel-money-in-uganda-4026838
A16: UG-015 | B16: 2022 | C16: Jun 2022 | D16: Uganda Securities Exchange (USE) & tech partner Soft Edge | E16: Financial Services | F16: Capital markets | H16: Data breach / exposure | I16: Unsecured server exposed investor database (~32 GB) for at least 12 days | J16: Unknown (discovered by researcher) | M16: Investor personal data incl. passwords & bank details | N16: PDPO investigation found USE and Soft Edge negligent (2023) | O16: Confirmed | P16: Daily Monitor; Unwanted Witness; PDPO | Q16: https://www.monitor.co.ug/uganda/business/markets/use-investor-data-was-exposed-to-hackers-investigation-finds--4306532
A17: UG-016 | B17: 2022 | C17: 28 Oct 2022 | D17: Airtel Mobile Commerce Uganda (Airtel Money) | E17: Financial Services | F17: Mobile money (telco-operated) | G17: Telecommunications; Banking; Microfinance | H17: Unauthorised access / system fraud | I17: Third-party betting platform used as gateway; software tweaked to auto-approve transactions; ~1,800 SIM cards used to withdraw | J17: Unknown syndicate | K17: 8 | L17: 2.1 | M17: Airtel-to-bank wallet & bulk payment system | N17: Airtel-to-bank services suspended; Airtel said balances unaffected | O17: Reported | P17: The EastAfrican; The Citizen; Pulse Uganda | Q17: https://www.theeastafrican.co.ke/tea/business-tech/how-hackers-used-betting-site-to-access-airtel-money-in-uganda-4027746 | R17: Early media estimates ranged UGX 30–50bn; later reporting ~UGX 8bn.
A18: UG-017 | B18: 2023 | C18: c. Jun–Jul 2023 | D18: Two major commercial banks (unnamed) | E18: Financial Services | F18: Commercial banking | H18: Ransomware / extortion | I18: Phishing-led intrusion; customer data accessed; USD 1m ransom demanded | J18: Suspected LockBit (per anonymous expert) | M18: Customer data incl. IDs, statements, credit history of high-net-worth clients | N18: Ransom refused; banks failed over to backup data centre | O18: Reported | P18: Daily Monitor | Q18: https://www.monitor.co.ug/uganda/special-reports/video-global-cartel-hacks-commercial-banks-demands-1m-4291218 | R18: Based on anonymous sources; date approximate.
A19: UG-018 | B19: 2024 | C19: Sep 2024 (reported Nov 2024) | D19: Bank of Uganda / Ministry of Finance Treasury | E19: Financial Services | F19: Central bank / public finance | G19: Government & Public Sector | H19: Unauthorised access / system fraud | I19: Two debt-service payments to IDA and AfDF diverted to private accounts in Japan and UK; insider collusion suspected | J19: 'Waste' group named in media; MoFPED officials charged | K19: 53.5 | L19: 14.73 | M19: Treasury payment systems | N19: Auditor General audit; 9 MoFPED officials committed for trial; over half of funds recovered | O19: Confirmed | P19: Daily Monitor; Reuters (via CNBC Africa); The Observer | Q19: https://www.monitor.co.ug/uganda/news/national/police-arrest-nine-govt-officials-over-bank-of-uganda-heist--4913192 | R19: Loss = USD 6.134m + USD 8.597m per audit. Media initially reported UGX 62bn (USD 16.8m).
A20: UG-019 | B20: 2025 | C20: 18 Aug 2025 | D20: Uganda Electricity Transmission Company Ltd (UETCL) | E20: Energy & Utilities | F20: Electricity transmission | H20: Ransomware / extortion | I20: Ransomware; grid monitoring systems compromised; data theft claimed | J20: Qilin ransomware group | M20: Grid monitoring systems; contracts, ID documents, financial statements (claimed) | N20: Service restored via backup protocols | O20: Confirmed | P20: The Independent (citing INTERPOL Africa Cyberthreat Assessment 2026) | Q20: https://www.independent.co.ug/the-hackers-are-coming-for-africas-critical-infrastructure/ | R20: INTERPOL describes it as a suspected ransomware incident.
A21: UG-020 | B21: 2026 | C21: Mar 2026 (Uganda update May 2026) | D21: Stanbic Bank Uganda (Standard Bank Group data incident) | E21: Financial Services | F21: Commercial banking | H21: Data breach / exposure | I21: Group-level data incident affecting a small set of Ugandan records | J21: Not disclosed | M21: Partial data: names, emails, phone numbers, account numbers | N21: Reported to PDPO; bank says no funds or core systems affected | O21: Confirmed | P21: Stanbic Bank Uganda statement | Q21: https://www.stanbicbank.co.ug/uganda/personal/about-us/news/An-Important-Data-Incident-Update
A22: UG-021 | B22: 2026 | C22: Early Jul 2026 (weekend) | D22: MTN Uganda & Stanbic Bank Uganda – service outages | E22: Telecommunications | F22: Mobile network & mobile money | G22: Financial Services | H22: Service disruption (cause disputed) | I22: Weekend outage of mobile money, data, ATMs, internet banking | J22: Unconfirmed | M22: Digital channels | N22: Services restored | O22: Disputed | P22: The EastAfrican; ChimpReports | Q22: https://chimpreports.com/mtn-stanbic-outages-spark-questions/ | R22: The EastAfrican called it a cyber attack; MTN cited a data-centre power outage and neither firm attributed it to an attack.
A23: UG-022 | B23: 2026 | C23: Jul 2026 | D23: Unnamed telecom and utility company systems | E23: Telecommunications | F23: Telecom networks | G23: Energy & Utilities | H23: Unauthorised access / system fraud | I23: Alleged syndicate breached telecom & utility systems causing disruptions and unauthorised deductions from customer accounts | J23: Transnational syndicate; 1,000+ foreign nationals detained | M23: Customer accounts; network systems | N23: Joint CID/immigration raids in Kampala & Wakiso; probe ongoing | O23: Alleged | P23: The African Mirror; The EastAfrican | Q23: https://theafricanmirror.africa/news/uganda-blows-open-continents-largest-cyber-fraud-bust-over-1000-foreigners-held-over-telecom-and-utility-hacking/ | R23: May be linked to the outage above; no official loss estimate published.

Sheet Sector Analysis
A1: Which sector is hit the most? – Uganda cyber incidents
A2: All figures are formulas over the Incidents sheet (rows 2–500), so they update as you add incidents.
A4: Most-hit sector (by incident count): | B4: =INDEX(A9:A16,MATCH(MAX(B9:B16),B9:B16,0)) -> Financial Services
A5: Share of all incidents: | B5: =INDEX(C9:C16,MATCH(MAX(B9:B16),B9:B16,0)) -> 0.45454545
A6: Share of quantified losses: | B6: =INDEX(G9:G16,MATCH(MAX(B9:B16),B9:B16,0)) -> 0.97714051
A8: Sector | B8: Incidents | C8: Share of Incidents | D8: Confirmed Incidents | E8: Incidents 2021–2026 | F8: Reported Loss (UGX bn) | G8: Share of Quantified Loss | H8: Rank (by incidents)
A9: Financial Services | B9: =COUNTIF(Incidents!$E$2:$E$500,A9) -> 10 | C9: =IF($B$17=0,0,B9/$B$17) -> 0.45454545 | D9: =COUNTIFS(Incidents!$E$2:$E$500,A9,Incidents!$O$2:$O$500,"Confirmed") -> 6 | E9: =COUNTIFS(Incidents!$E$2:$E$500,A9,Incidents!$B$2:$B$500,">=2021") -> 6 | F9: =SUMIF(Incidents!$E$2:$E$500,A9,Incidents!$K$2:$K$500) -> 85.491 | G9: =IF($F$17=0,0,F9/$F$17) -> 0.97714051 | H9: =IF(B9=0,"-",RANK(B9,$B$9:$B$16)) -> 1
A10: Government & Public Sector | B10: =COUNTIF(Incidents!$E$2:$E$500,A10) -> 7 | C10: =IF($B$17=0,0,B10/$B$17) -> 0.31818182 | D10: =COUNTIFS(Incidents!$E$2:$E$500,A10,Incidents!$O$2:$O$500,"Confirmed") -> 1 | E10: =COUNTIFS(Incidents!$E$2:$E$500,A10,Incidents!$B$2:$B$500,">=2021") -> 2 | F10: =SUMIF(Incidents!$E$2:$E$500,A10,Incidents!$K$2:$K$500) -> 2 | G10: =IF($F$17=0,0,F10/$F$17) -> 0.022859494 | H10: =IF(B10=0,"-",RANK(B10,$B$9:$B$16)) -> 2
A11: Telecommunications | B11: =COUNTIF(Incidents!$E$2:$E$500,A11) -> 2 | C11: =IF($B$17=0,0,B11/$B$17) -> 0.090909091 | D11: =COUNTIFS(Incidents!$E$2:$E$500,A11,Incidents!$O$2:$O$500,"Confirmed") -> 0 | E11: =COUNTIFS(Incidents!$E$2:$E$500,A11,Incidents!$B$2:$B$500,">=2021") -> 2 | F11: =SUMIF(Incidents!$E$2:$E$500,A11,Incidents!$K$2:$K$500) -> 0 | G11: =IF($F$17=0,0,F11/$F$17) -> 0 | H11: =IF(B11=0,"-",RANK(B11,$B$9:$B$16)) -> 3
A12: Education | B12: =COUNTIF(Incidents!$E$2:$E$500,A12) -> 2 | C12: =IF($B$17=0,0,B12/$B$17) -> 0.090909091 | D12: =COUNTIFS(Incidents!$E$2:$E$500,A12,Incidents!$O$2:$O$500,"Confirmed") -> 1 | E12: =COUNTIFS(Incidents!$E$2:$E$500,A12,Incidents!$B$2:$B$500,">=2021") -> 0 | F12: =SUMIF(Incidents!$E$2:$E$500,A12,Incidents!$K$2:$K$500) -> 0 | G12: =IF($F$17=0,0,F12/$F$17) -> 0 | H12: =IF(B12=0,"-",RANK(B12,$B$9:$B$16)) -> 3
A13: Energy & Utilities | B13: =COUNTIF(Incidents!$E$2:$E$500,A13) -> 1 | C13: =IF($B$17=0,0,B13/$B$17) -> 0.045454545 | D13: =COUNTIFS(Incidents!$E$2:$E$500,A13,Incidents!$O$2:$O$500,"Confirmed") -> 1 | E13: =COUNTIFS(Incidents!$E$2:$E$500,A13,Incidents!$B$2:$B$500,">=2021") -> 1 | F13: =SUMIF(Incidents!$E$2:$E$500,A13,Incidents!$K$2:$K$500) -> 0 | G13: =IF($F$17=0,0,F13/$F$17) -> 0 | H13: =IF(B13=0,"-",RANK(B13,$B$9:$B$16)) -> 5
A14: Health | B14: =COUNTIF(Incidents!$E$2:$E$500,A14) -> 0 | C14: =IF($B$17=0,0,B14/$B$17) -> 0 | D14: =COUNTIFS(Incidents!$E$2:$E$500,A14,Incidents!$O$2:$O$500,"Confirmed") -> 0 | E14: =COUNTIFS(Incidents!$E$2:$E$500,A14,Incidents!$B$2:$B$500,">=2021") -> 0 | F14: =SUMIF(Incidents!$E$2:$E$500,A14,Incidents!$K$2:$K$500) -> 0 | G14: =IF($F$17=0,0,F14/$F$17) -> 0 | H14: =IF(B14=0,"-",RANK(B14,$B$9:$B$16)) -> -
A15: Media | B15: =COUNTIF(Incidents!$E$2:$E$500,A15) -> 0 | C15: =IF($B$17=0,0,B15/$B$17) -> 0 | D15: =COUNTIFS(Incidents!$E$2:$E$500,A15,Incidents!$O$2:$O$500,"Confirmed") -> 0 | E15: =COUNTIFS(Incidents!$E$2:$E$500,A15,Incidents!$B$2:$B$500,">=2021") -> 0 | F15: =SUMIF(Incidents!$E$2:$E$500,A15,Incidents!$K$2:$K$500) -> 0 | G15: =IF($F$17=0,0,F15/$F$17) -> 0 | H15: =IF(B15=0,"-",RANK(B15,$B$9:$B$16)) -> -
A16: Other | B16: =COUNTIF(Incidents!$E$2:$E$500,A16) -> 0 | C16: =IF($B$17=0,0,B16/$B$17) -> 0 | D16: =COUNTIFS(Incidents!$E$2:$E$500,A16,Incidents!$O$2:$O$500,"Confirmed") -> 0 | E16: =COUNTIFS(Incidents!$E$2:$E$500,A16,Incidents!$B$2:$B$500,">=2021") -> 0 | F16: =SUMIF(Incidents!$E$2:$E$500,A16,Incidents!$K$2:$K$500) -> 0 | G16: =IF($F$17=0,0,F16/$F$17) -> 0 | H16: =IF(B16=0,"-",RANK(B16,$B$9:$B$16)) -> -
A17: Total | B17: =SUM(B9:B16) -> 22 | C17: =SUM(C9:C16) -> 1 | D17: =SUM(D9:D16) -> 9 | E17: =SUM(E9:E16) -> 11 | F17: =SUM(F9:F16) -> 87.491 | G17: =SUM(G9:G16) -> 1
A18: Losses only count incidents with a published figure; most incidents have no disclosed loss.
A19: Incidents by sector and period
A20: Sector | B20: 2011–2015 | C20: 2016–2020 | D20: 2021–2026
A21: Financial Services | B21: =COUNTIFS(Incidents!$E$2:$E$500,$A21,Incidents!$B$2:$B$500,">=2011",Incidents!$B$2:$B$500,"<=2015") -> 2 | C21: =COUNTIFS(Incidents!$E$2:$E$500,$A21,Incidents!$B$2:$B$500,">=2016",Incidents!$B$2:$B$500,"<=2020") -> 2 | D21: =COUNTIFS(Incidents!$E$2:$E$500,$A21,Incidents!$B$2:$B$500,">=2021",Incidents!$B$2:$B$500,"<=2026") -> 6
A22: Government & Public Sector | B22: =COUNTIFS(Incidents!$E$2:$E$500,$A22,Incidents!$B$2:$B$500,">=2011",Incidents!$B$2:$B$500,"<=2015") -> 3 | C22: =COUNTIFS(Incidents!$E$2:$E$500,$A22,Incidents!$B$2:$B$500,">=2016",Incidents!$B$2:$B$500,"<=2020") -> 2 | D22: =COUNTIFS(Incidents!$E$2:$E$500,$A22,Incidents!$B$2:$B$500,">=2021",Incidents!$B$2:$B$500,"<=2026") -> 2
A23: Telecommunications | B23: =COUNTIFS(Incidents!$E$2:$E$500,$A23,Incidents!$B$2:$B$500,">=2011",Incidents!$B$2:$B$500,"<=2015") -> 0 | C23: =COUNTIFS(Incidents!$E$2:$E$500,$A23,Incidents!$B$2:$B$500,">=2016",Incidents!$B$2:$B$500,"<=2020") -> 0 | D23: =COUNTIFS(Incidents!$E$2:$E$500,$A23,Incidents!$B$2:$B$500,">=2021",Incidents!$B$2:$B$500,"<=2026") -> 2
A24: Education | B24: =COUNTIFS(Incidents!$E$2:$E$500,$A24,Incidents!$B$2:$B$500,">=2011",Incidents!$B$2:$B$500,"<=2015") -> 1 | C24: =COUNTIFS(Incidents!$E$2:$E$500,$A24,Incidents!$B$2:$B$500,">=2016",Incidents!$B$2:$B$500,"<=2020") -> 1 | D24: =COUNTIFS(Incidents!$E$2:$E$500,$A24,Incidents!$B$2:$B$500,">=2021",Incidents!$B$2:$B$500,"<=2026") -> 0
A25: Energy & Utilities | B25: =COUNTIFS(Incidents!$E$2:$E$500,$A25,Incidents!$B$2:$B$500,">=2011",Incidents!$B$2:$B$500,"<=2015") -> 0 | C25: =COUNTIFS(Incidents!$E$2:$E$500,$A25,Incidents!$B$2:$B$500,">=2016",Incidents!$B$2:$B$500,"<=2020") -> 0 | D25: =COUNTIFS(Incidents!$E$2:$E$500,$A25,Incidents!$B$2:$B$500,">=2021",Incidents!$B$2:$B$500,"<=2026") -> 1
A27: Incidents by type
A28: Incident Type | B28: Incidents | C28: Of which Financial Services
A29: Unauthorised access / system fraud | B29: =COUNTIF(Incidents!$H$2:$H$500,A29) -> 6 | C29: =COUNTIFS(Incidents!$H$2:$H$500,A29,Incidents!$E$2:$E$500,"Financial Services") -> 4
A30: Website defacement / hacktivism | B30: =COUNTIF(Incidents!$H$2:$H$500,A30) -> 5 | C30: =COUNTIFS(Incidents!$H$2:$H$500,A30,Incidents!$E$2:$E$500,"Financial Services") -> 0
A31: Data breach / exposure | B31: =COUNTIF(Incidents!$H$2:$H$500,A31) -> 3 | C31: =COUNTIFS(Incidents!$H$2:$H$500,A31,Incidents!$E$2:$E$500,"Financial Services") -> 2
A32: Insider fraud | B32: =COUNTIF(Incidents!$H$2:$H$500,A32) -> 2 | C32: =COUNTIFS(Incidents!$H$2:$H$500,A32,Incidents!$E$2:$E$500,"Financial Services") -> 2
A33: Unauthorised access / records manipulation | B33: =COUNTIF(Incidents!$H$2:$H$500,A33) -> 2 | C33: =COUNTIFS(Incidents!$H$2:$H$500,A33,Incidents!$E$2:$E$500,"Financial Services") -> 0
A34: Ransomware / extortion | B34: =COUNTIF(Incidents!$H$2:$H$500,A34) -> 2 | C34: =COUNTIFS(Incidents!$H$2:$H$500,A34,Incidents!$E$2:$E$500,"Financial Services") -> 1
A35: SIM-swap fraud | B35: =COUNTIF(Incidents!$H$2:$H$500,A35) -> 1 | C35: =COUNTIFS(Incidents!$H$2:$H$500,A35,Incidents!$E$2:$E$500,"Financial Services") -> 1
A36: Service disruption (cause disputed) | B36: =COUNTIF(Incidents!$H$2:$H$500,A36) -> 1 | C36: =COUNTIFS(Incidents!$H$2:$H$500,A36,Incidents!$E$2:$E$500,"Financial Services") -> 0
A38: Inside Financial Services: which sub-sector?
A39: Sub-sector | B39: Incidents | C39: Reported Loss (UGX bn)
A40: Banking & mobile money | B40: =COUNTIFS(Incidents!$E$2:$E$500,"Financial Services",Incidents!$F$2:$F$500,A40) -> 1 | C40: =SUMIFS(Incidents!$K$2:$K$500,Incidents!$E$2:$E$500,"Financial Services",Incidents!$F$2:$F$500,A40) -> 0
A41: Capital markets | B41: =COUNTIFS(Incidents!$E$2:$E$500,"Financial Services",Incidents!$F$2:$F$500,A41) -> 1 | C41: =SUMIFS(Incidents!$K$2:$K$500,Incidents!$E$2:$E$500,"Financial Services",Incidents!$F$2:$F$500,A41) -> 0
A42: Central bank / public finance | B42: =COUNTIFS(Incidents!$E$2:$E$500,"Financial Services",Incidents!$F$2:$F$500,A42) -> 1 | C42: =SUMIFS(Incidents!$K$2:$K$500,Incidents!$E$2:$E$500,"Financial Services",Incidents!$F$2:$F$500,A42) -> 53.5
A43: Commercial banking | B43: =COUNTIFS(Incidents!$E$2:$E$500,"Financial Services",Incidents!$F$2:$F$500,A43) -> 2 | C43: =SUMIFS(Incidents!$K$2:$K$500,Incidents!$E$2:$E$500,"Financial Services",Incidents!$F$2:$F$500,A43) -> 0
A44: Microfinance (MDI) | B44: =COUNTIFS(Incidents!$E$2:$E$500,"Financial Services",Incidents!$F$2:$F$500,A44) -> 1 | C44: =SUMIFS(Incidents!$K$2:$K$500,Incidents!$E$2:$E$500,"Financial Services",Incidents!$F$2:$F$500,A44) -> 0.4
...

Sheet National Stats
A1: National cybercrime indicators – Uganda
A2: Aggregate figures from police and industry reports. Sources disagree in places – see Notes column.
A4: Year | B4: Cybercrime Cases Reported to Police | C4: Change vs Prior Listed Year | D4: Reported Losses (UGX bn) | E4: Recovered (UGX bn) | F4: Source | G4: Notes
A5: 2019 | C5: - | D5: 11.4466 | E5: 0.0519 | F5: Serianu Africa Cybersecurity Report – Uganda 2019/2020 (citing Uganda Police) | G5: Case count not given in source.
A6: 2022 | B6: 286 | C6: =IF(OR(B6="",B5=""),"-",B6/B5-1) -> - | D6: 19.2 | F6: Uganda Police Annual Crime Report 2025 (via The EastAfrican); loss via Daily Monitor
A7: 2023 | B7: 245 | C7: =IF(OR(B7="",B6=""),"-",B7/B6-1) -> -0.14335664 | D7: 5 | F7: Uganda Police (via The EastAfrican & Daily Monitor) | G7: Monitor reports 'over 245 cases' and ~UGX 5bn loss.
A8: 2024 | B8: 474 | C8: =IF(OR(B8="",B7=""),"-",B8/B7-1) -> 0.93469388 | D8: 72.1 | E8: 0.42 | F8: Uganda Police Annual Crime Report 2024 (via Nile Post, Kikubo Lane) | G8: The EastAfrican (Jul 2026) cites UGX 41bn for 2024 – figures conflict.
A9: 2025 | B9: 412 | C9: =IF(OR(B9="",B8=""),"-",B9/B8-1) -> -0.13080169 | F9: Uganda Police Annual Crime Report 2025 (via The EastAfrican) | G9: Loss figure not found.
A11: Other indicators (financial sector focus)
A12: Period | B12: Indicator | C12: Value | D12: Source
A13: 2024 | B13: Licensed financial institutions affected by cybercrime | C13: More than 20 | D13: Uganda Police Force (via The EastAfrican, Jul 2026)
A14: 2024 | B14: Banking fraud cases / value | C14: 110 cases / UGX 5.3bn | D14: Uganda Bankers Association (via The EastAfrican)
A15: 2024 | B15: Digital fraud as share of all fraud cases | C15: 31.9% | D15: Uganda Police Annual Cyber Crime Report (via Nile Post)
A16: Year to Oct 2021 | B16: Losses by Ugandan banks to hackers | C16: > USD 4m (USD 3m from 10 bank-fraud cases) | D16: INTERPOL Uganda (via The EastAfrican)
A17: 2022 | B17: SMEs that experienced cyberattacks | C17: 40% | D17: NITA-U study (via Nile Post)
A18: 2019 | B18: Fraudulently swapped SIM cards used to steal from banks & mobile money | C18: 519 | D18: Serianu report (citing Uganda Police)

Sheet Notes & Method
A1: About this dataset
A3: Compiled | B3: 15 September 2026, from public media reports, company statements, police/INTERPOL figures and regulator findings.
A4: Scope | B4: Publicly reported cyber incidents where a Ugandan organisation (or its systems) was the victim, 2011–2026. Scam call centres targeting people abroad and purely physical thefts are excluded.
A5: Sector (Primary) | B5: Sector of the main victim organisation. Mobile money is classed as Financial Services (it is regulated as a payment service), with Telecommunications listed under 'Other Sectors Affected'. Use the Sub-sector column to split it out if you prefer.
A6: Confirmed | B6: Acknowledged by the victim, a regulator, court, police or INTERPOL.
A7: Reported | B7: Covered by credible media but not formally confirmed, or based on anonymous sources / attacker claims.
A8: Alleged | B8: Early-stage allegations from an ongoing investigation.
A9: Disputed | B9: Media called it a cyber attack but the organisations gave a different cause.
A10: Loss figures | B10: 'Reported Loss' is the best available published figure; many incidents have no disclosed amount, so sector loss totals understate reality. USD is only filled where a source gave it.
A11: Main limitation | B11: This is a list of publicised incidents, not a complete census. Ugandan banks have historically kept incidents quiet to protect their reputation, and the police recorded 474 cybercrime cases in 2024 alone, so the true count is far higher. Treat the sector ranking as indicative.
A12: Adding incidents | B12: Add a new row at the bottom of the Incidents sheet (up to row 500). Pick Sector and Confidence from the dropdowns; the Sector Analysis sheet updates automatically.
A13: Items to double-check | B13: UG-007 (date approximate), UG-017 (anonymous sources), UG-021 and UG-022 (July 2026 events still under investigation).
